Workbook

Sheet A股
A1: 股票分析表生成器｜财务年度 2025｜交易统计年度 2026｜运行日期 2026-08-29｜金额：亿元；股数：亿股
A2: 范围：上交所、深交所、北交所普通 A 股；不含 B 股、基金、债券等非普通股票。
A3: 公司信息 | E3: 营业收入 | H3: 毛利率 | K3: 归母净利润 | O3: 经营活动现金流 | R3: 上市发行与市场交易 | AC3: 数据状态
A4: 证券代码 | B4: 公司名称 | C4: 实际报告期 | D4: 报表币种 | E4: 2025年营业收入 | F4: 营业收入同比 | G4: 营业收入三年 CAGR | H4: 毛利率 | I4: 毛利率同比变化（百分点） | J4: 毛利率三年变化（百分点） | K4: 归母净利润 | L4: 归母净利率 | M4: 归母净利润同比 | N4: 归母净利润三年 CAGR | O4: 经营活动现金流净额 | P4: 经营活动现金流同比 | Q4: 经营活动现金流三年 CAGR | R4: 最新总市值 | S4: 上市日期 | T4: 发行价 | U4: 发行股数 | V4: 发行时总市值 | W4: 现价 | X4: 市值增长率 | Y4: 当年累计大宗交易笔数 | Z4: 当年累计大宗交易金额 | AA4: 近五个交易日资金净额 | AB4: 近一月资金净额（最近22个交易日） | AC4: 字段状态摘要 | AD4: 公司状态
A5: 920985 | B5: 海泰新能 | C5: =IF('历史数据'!D3="","",'历史数据'!D3) | D5: =IF('历史数据'!E3="","",'历史数据'!E3) | E5: =IF('历史数据'!G3="","",'历史数据'!G3/100000000) | F5: =IF(OR('历史数据'!G3="",'历史数据'!H3<=0),"",'历史数据'!G3/'历史数据'!H3-1) | G5: =IF(OR('历史数据'!G3<=0,'历史数据'!I3<=0),"",POWER('历史数据'!G3/'历史数据'!I3,1/3)-1) | H5: =IF(OR('历史数据'!G3<=0,'历史数据'!J3=""),"",('历史数据'!G3-'历史数据'!J3)/'历史数据'!G3) | I5: =IF(OR(H5="",'历史数据'!H3<=0,'历史数据'!K3=""),"",(H5-('历史数据'!H3-'历史数据'!K3)/'历史数据'!H3)*100) | J5: =IF(OR(H5="",'历史数据'!I3<=0,'历史数据'!L3=""),"",(H5-('历史数据'!I3-'历史数据'!L3)/'历史数据'!I3)*100) | K5: =IF('历史数据'!M3="","",'历史数据'!M3/100000000) | L5: =IF(OR('历史数据'!G3=0,'历史数据'!M3=""),"",'历史数据'!M3/'历史数据'!G3) | M5: =IF(OR('历史数据'!M3="",'历史数据'!N3=0),"",('历史数据'!M3-'历史数据'!N3)/ABS('历史数据'!N3)) | N5: =IF(OR('历史数据'!M3<=0,'历史数据'!O3<=0),"",POWER('历史数据'!M3/'历史数据'!O3,1/3)-1) | O5: =IF('历史数据'!P3="","",'历史数据'!P3/100000000) | P5: =IF(OR('历史数据'!P3="",'历史数据'!Q3=0),"",('历史数据'!P3-'历史数据'!Q3)/ABS('历史数据'!Q3)) | Q5: =IF(OR('历史数据'!P3<=0,'历史数据'!R3<=0),"",POWER('历史数据'!P3/'历史数据'!R3,1/3)-1) | R5: =IF('历史数据'!S3="","",'历史数据'!S3/100000000) | S5: =IF('历史数据'!T3="","",'历史数据'!T3) | T5: =IF('历史数据'!U3="","",'历史数据'!U3) | U5: =IF('历史数据'!V3="","",'历史数据'!V3/100000000) | V5: =IF('历史数据'!W3="","",'历史数据'!W3/100000000) | W5: =IF('历史数据'!X3="","",'历史数据'!X3) | X5: =IF(OR(R5="",V5<=0),"",R5/V5-1) | Y5: =IF('历史数据'!Y3="","",'历史数据'!Y3) | Z5: =IF('历史数据'!Z3="","",'历史数据'!Z3/100000000) | AA5: =IF('历史数据'!AA3="","",'历史数据'!AA3/100000000) | AB5: =IF('历史数据'!AB3="","",'历史数据'!AB3/100000000) | AC5: 近五个交易日资金净额:optional_missing；近一月资金净额（最近22个交易日）:optional_missing | AD5: SUCCESS
A6: 920982 | B6: 锦波生物 | C6: =IF('历史数据'!D4="","",'历史数据'!D4) | D6: =IF('历史数据'!E4="","",'历史数据'!E4) | E6: =IF('历史数据'!G4="","",'历史数据'!G4/100000000) | F6: =IF(OR('历史数据'!G4="",'历史数据'!H4<=0),"",'历史数据'!G4/'历史数据'!H4-1) | G6: =IF(OR('历史数据'!G4<=0,'历史数据'!I4<=0),"",POWER('历史数据'!G4/'历史数据'!I4,1/3)-1) | H6: =IF(OR('历史数据'!G4<=0,'历史数据'!J4=""),"",('历史数据'!G4-'历史数据'!J4)/'历史数据'!G4) | I6: =IF(OR(H6="",'历史数据'!H4<=0,'历史数据'!K4=""),"",(H6-('历史数据'!H4-'历史数据'!K4)/'历史数据'!H4)*100) | J6: =IF(OR(H6="",'历史数据'!I4<=0,'历史数据'!L4=""),"",(H6-('历史数据'!I4-'历史数据'!L4)/'历史数据'!I4)*100) | K6: =IF('历史数据'!M4="","",'历史数据'!M4/100000000) | L6: =IF(OR('历史数据'!G4=0,'历史数据'!M4=""),"",'历史数据'!M4/'历史数据'!G4) | M6: =IF(OR('历史数据'!M4="",'历史数据'!N4=0),"",('历史数据'!M4-'历史数据'!N4)/ABS('历史数据'!N4)) | N6: =IF(OR('历史数据'!M4<=0,'历史数据'!O4<=0),"",POWER('历史数据'!M4/'历史数据'!O4,1/3)-1) | O6: =IF('历史数据'!P4="","",'历史数据'!P4/100000000) | P6: =IF(OR('历史数据'!P4="",'历史数据'!Q4=0),"",('历史数据'!P4-'历史数据'!Q4)/ABS('历史数据'!Q4)) | Q6: =IF(OR('历史数据'!P4<=0,'历史数据'!R4<=0),"",POWER('历史数据'!P4/'历史数据'!R4,1/3)-1) | R6: =IF('历史数据'!S4="","",'历史数据'!S4/100000000) | S6: =IF('历史数据'!T4="","",'历史数据'!T4) | T6: =IF('历史数据'!U4="","",'历史数据'!U4) | U6: =IF('历史数据'!V4="","",'历史数据'!V4/100000000) | V6: =IF('历史数据'!W4="","",'历史数据'!W4/100000000) | W6: =IF('历史数据'!X4="","",'历史数据'!X4) | X6: =IF(OR(R6="",V6<=0),"",R6/V6-1) | Y6: =IF('历史数据'!Y4="","",'历史数据'!Y4) | Z6: =IF('历史数据'!Z4="","",'历史数据'!Z4/100000000) | AA6: =IF('历史数据'!AA4="","",'历史数据'!AA4/100000000) | AB6: =IF('历史数据'!AB4="","",'历史数据'!AB4/100000000) | AC6: 近五个交易日资金净额:optional_missing；近一月资金净额（最近22个交易日）:optional_missing | AD6: SUCCESS
A7: 920978 | B7: 开特股份 | C7: =IF('历史数据'!D6="","",'历史数据'!D6) | D7: =IF('历史数据'!E6="","",'历史数据'!E6) | E7: =IF('历史数据'!G6="","",'历史数据'!G6/100000000) | F7: =IF(OR('历史数据'!G6="",'历史数据'!H6<=0),"",'历史数据'!G6/'历史数据'!H6-1) | G7: =IF(OR('历史数据'!G6<=0,'历史数据'!I6<=0),"",POWER('历史数据'!G6/'历史数据'!I6,1/3)-1) | H7: =IF(OR('历史数据'!G6<=0,'历史数据'!J6=""),"",('历史数据'!G6-'历史数据'!J6)/'历史数据'!G6) | I7: =IF(OR(H7="",'历史数据'!H6<=0,'历史数据'!K6=""),"",(H7-('历史数据'!H6-'历史数据'!K6)/'历史数据'!H6)*100) | J7: =IF(OR(H7="",'历史数据'!I6<=0,'历史数据'!L6=""),"",(H7-('历史数据'!I6-'历史数据'!L6)/'历史数据'!I6)*100) | K7: =IF('历史数据'!M6="","",'历史数据'!M6/100000000) | L7: =IF(OR('历史数据'!G6=0,'历史数据'!M6=""),"",'历史数据'!M6/'历史数据'!G6) | M7: =IF(OR('历史数据'!M6="",'历史数据'!N6=0),"",('历史数据'!M6-'历史数据'!N6)/ABS('历史数据'!N6)) | N7: =IF(OR('历史数据'!M6<=0,'历史数据'!O6<=0),"",POWER('历史数据'!M6/'历史数据'!O6,1/3)-1) | O7: =IF('历史数据'!P6="","",'历史数据'!P6/100000000) | P7: =IF(OR('历史数据'!P6="",'历史数据'!Q6=0),"",('历史数据'!P6-'历史数据'!Q6)/ABS('历史数据'!Q6)) | Q7: =IF(OR('历史数据'!P6<=0,'历史数据'!R6<=0),"",POWER('历史数据'!P6/'历史数据'!R6,1/3)-1) | R7: =IF('历史数据'!S6="","",'历史数据'!S6/100000000) | S7: =IF('历史数据'!T6="","",'历史数据'!T6) | T7: =IF('历史数据'!U6="","",'历史数据'!U6) | U7: =IF('历史数据'!V6="","",'历史数据'!V6/100000000) | V7: =IF('历史数据'!W6="","",'历史数据'!W6/100000000) | W7: =IF('历史数据'!X6="","",'历史数据'!X6) | X7: =IF(OR(R7="",V7<=0),"",R7/V7-1) | Y7: =IF('历史数据'!Y6="","",'历史数据'!Y6) | Z7: =IF('历史数据'!Z6="","",'历史数据'!Z6/100000000) | AA7: =IF('历史数据'!AA6="","",'历史数据'!AA6/100000000) | AB7: =IF('历史数据'!AB6="","",'历史数据'!AB6/100000000) | AC7: 近五个交易日资金净额:optional_missing；近一月资金净额（最近22个交易日）:optional_missing | AD7: SUCCESS
A8: 920974 | B8: 凯大催化 | C8: =IF('历史数据'!D8="","",'历史数据'!D8) | D8: =IF('历史数据'!E8="","",'历史数据'!E8) | E8: =IF('历史数据'!G8="","",'历史数据'!G8/100000000) | F8: =IF(OR('历史数据'!G8="",'历史数据'!H8<=0),"",'历史数据'!G8/'历史数据'!H8-1) | G8: =IF(OR('历史数据'!G8<=0,'历史数据'!I8<=0),"",POWER('历史数据'!G8/'历史数据'!I8,1/3)-1) | H8: =IF(OR('历史数据'!G8<=0,'历史数据'!J8=""),"",('历史数据'!G8-'历史数据'!J8)/'历史数据'!G8) | I8: =IF(OR(H8="",'历史数据'!H8<=0,'历史数据'!K8=""),"",(H8-('历史数据'!H8-'历史数据'!K8)/'历史数据'!H8)*100) | J8: =IF(OR(H8="",'历史数据'!I8<=0,'历史数据'!L8=""),"",(H8-('历史数据'!I8-'历史数据'!L8)/'历史数据'!I8)*100) | K8: =IF('历史数据'!M8="","",'历史数据'!M8/100000000) | L8: =IF(OR('历史数据'!G8=0,'历史数据'!M8=""),"",'历史数据'!M8/'历史数据'!G8) | M8: =IF(OR('历史数据'!M8="",'历史数据'!N8=0),"",('历史数据'!M8-'历史数据'!N8)/ABS('历史数据'!N8)) | N8: =IF(OR('历史数据'!M8<=0,'历史数据'!O8<=0),"",POWER('历史数据'!M8/'历史数据'!O8,1/3)-1) | O8: =IF('历史数据'!P8="","",'历史数据'!P8/100000000) | P8: =IF(OR('历史数据'!P8="",'历史数据'!Q8=0),"",('历史数据'!P8-'历史数据'!Q8)/ABS('历史数据'!Q8)) | Q8: =IF(OR('历史数据'!P8<=0,'历史数据'!R8<=0),"",POWER('历史数据'!P8/'历史数据'!R8,1/3)-1) | R8: =IF('历史数据'!S8="","",'历史数据'!S8/100000000) | S8: =IF('历史数据'!T8="","",'历史数据'!T8) | T8: =IF('历史数据'!U8="","",'历史数据'!U8) | U8: =IF('历史数据'!V8="","",'历史数据'!V8/100000000) | V8: =IF('历史数据'!W8="","",'历史数据'!W8/100000000) | W8: =IF('历史数据'!X8="","",'历史数据'!X8) | X8: =IF(OR(R8="",V8<=0),"",R8/V8-1) | Y8: =IF('历史数据'!Y8="","",'历史数据'!Y8) | Z8: =IF('历史数据'!Z8="","",'历史数据'!Z8/100000000) | AA8: =IF('历史数据'!AA8="","",'历史数据'!AA8/100000000) | AB8: =IF('历史数据'!AB8="","",'历史数据'!AB8/100000000) | AC8: 近五个交易日资金净额:optional_missing；近一月资金净额（最近22个交易日）:optional_missing | AD8: SUCCESS
A9: 920964 | B9: 润农节水 | C9: =IF('历史数据'!D11="","",'历史数据'!D11) | D9: =IF('历史数据'!E11="","",'历史数据'!E11) | E9: =IF('历史数据'!G11="","",'历史数据'!G11/100000000) | F9: =IF(OR('历史数据'!G11="",'历史数据'!H11<=0),"",'历史数据'!G11/'历史数据'!H11-1) | G9: =IF(OR('历史数据'!G11<=0,'历史数据'!I11<=0),"",POWER('历史数据'!G11/'历史数据'!I11,1/3)-1) | H9: =IF(OR('历史数据'!G11<=0,'历史数据'!J11=""),"",('历史数据'!G11-'历史数据'!J11)/'历史数据'!G11) | I9: =IF(OR(H9="",'历史数据'!H11<=0,'历史数据'!K11=""),"",(H9-('历史数据'!H11-'历史数据'!K11)/'历史数据'!H11)*100) | J9: =IF(OR(H9="",'历史数据'!I11<=0,'历史数据'!L11=""),"",(H9-('历史数据'!I11-'历史数据'!L11)/'历史数据'!I11)*100) | K9: =IF('历史数据'!M11="","",'历史数据'!M11/100000000) | L9: =IF(OR('历史数据'!G11=0,'历史数据'!M11=""),"",'历史数据'!M11/'历史数据'!G11) | M9: =IF(OR('历史数据'!M11="",'历史数据'!N11=0),"",('历史数据'!M11-'历史数据'!N11)/ABS('历史数据'!N11)) | N9: =IF(OR('历史数据'!M11<=0,'历史数据'!O11<=0),"",POWER('历史数据'!M11/'历史数据'!O11,1/3)-1) | O9: =IF('历史数据'!P11="","",'历史数据'!P11/100000000) | P9: =IF(OR('历史数据'!P11="",'历史数据'!Q11=0),"",('历史数据'!P11-'历史数据'!Q11)/ABS('历史数据'!Q11)) | Q9: =IF(OR('历史数据'!P11<=0,'历史数据'!R11<=0),"",POWER('历史数据'!P11/'历史数据'!R11,1/3)-1) | R9: =IF('历史数据'!S11="","",'历史数据'!S11/100000000) | S9: =IF('历史数据'!T11="","",'历史数据'!T11) | T9: =IF('历史数据'!U11="","",'历史数据'!U11) | U9: =IF('历史数据'!V11="","",'历史数据'!V11/100000000) | V9: =IF('历史数据'!W11="","",'历史数据'!W11/100000000) | W9: =IF('历史数据'!X11="","",'历史数据'!X11) | X9: =IF(OR(R9="",V9<=0),"",R9/V9-1) | Y9: =IF('历史数据'!Y11="","",'历史数据'!Y11) | Z9: =IF('历史数据'!Z11="","",'历史数据'!Z11/100000000) | AA9: =IF('历史数据'!AA11="","",'历史数据'!AA11/100000000) | AB9: =IF('历史数据'!AB11="","",'历史数据'!AB11/100000000) | AC9: 近五个交易日资金净额:optional_missing；近一月资金净额（最近22个交易日）:optional_missing | AD9: SUCCESS
A10: 920981 | B10: 晶赛科技 | C10: =IF('历史数据'!D5="","",'历史数据'!D5) | D10: =IF('历史数据'!E5="","",'历史数据'!E5) | E10: =IF('历史数据'!G5="","",'历史数据'!G5/100000000) | F10: =IF(OR('历史数据'!G5="",'历史数据'!H5<=0),"",'历史数据'!G5/'历史数据'!H5-1) | G10: =IF(OR('历史数据'!G5<=0,'历史数据'!I5<=0),"",POWER('历史数据'!G5/'历史数据'!I5,1/3)-1) | H10: =IF(OR('历史数据'!G5<=0,'历史数据'!J5=""),"",('历史数据'!G5-'历史数据'!J5)/'历史数据'!G5) | I10: =IF(OR(H10="",'历史数据'!H5<=0,'历史数据'!K5=""),"",(H10-('历史数据'!H5-'历史数据'!K5)/'历史数据'!H5)*100) | J10: =IF(OR(H10="",'历史数据'!I5<=0,'历史数据'!L5=""),"",(H10-('历史数据'!I5-'历史数据'!L5)/'历史数据'!I5)*100) | K10: =IF('历史数据'!M5="","",'历史数据'!M5/100000000) | L10: =IF(OR('历史数据'!G5=0,'历史数据'!M5=""),"",'历史数据'!M5/'历史数据'!G5) | M10: =IF(OR('历史数据'!M5="",'历史数据'!N5=0),"",('历史数据'!M5-'历史数据'!N5)/ABS('历史数据'!N5)) | N10: =IF(OR('历史数据'!M5<=0,'历史数据'!O5<=0),"",POWER('历史数据'!M5/'历史数据'!O5,1/3)-1) | O10: =IF('历史数据'!P5="","",'历史数据'!P5/100000000) | P10: =IF(OR('历史数据'!P5="",'历史数据'!Q5=0),"",('历史数据'!P5-'历史数据'!Q5)/ABS('历史数据'!Q5)) | Q10: =IF(OR('历史数据'!P5<=0,'历史数据'!R5<=0),"",POWER('历史数据'!P5/'历史数据'!R5,1/3)-1) | R10: =IF('历史数据'!S5="","",'历史数据'!S5/100000000) | S10: =IF('历史数据'!T5="","",'历史数据'!T5) | T10: =IF('历史数据'!U5="","",'历史数据'!U5) | U10: =IF('历史数据'!V5="","",'历史数据'!V5/100000000) | V10: =IF('历史数据'!W5="","",'历史数据'!W5/100000000) | W10: =IF('历史数据'!X5="","",'历史数据'!X5) | X10: =IF(OR(R10="",V10<=0),"",R10/V10-1) | Y10: =IF('历史数据'!Y5="","",'历史数据'!Y5) | Z10: =IF('历史数据'!Z5="","",'历史数据'!Z5/100000000) | AA10: =IF('历史数据'!AA5="","",'历史数据'!AA5/100000000) | AB10: =IF('历史数据'!AB5="","",'历史数据'!AB5/100000000) | AC10: 近五个交易日资金净额:optional_missing；近一月资金净额（最近22个交易日）:optional_missing | AD10: SUCCESS
A11: 920992 | B11: 中科美菱 | C11: =IF('历史数据'!D2="","",'历史数据'!D2) | D11: =IF('历史数据'!E2="","",'历史数据'!E2) | E11: =IF('历史数据'!G2="","",'历史数据'!G2/100000000) | F11: =IF(OR('历史数据'!G2="",'历史数据'!H2<=0),"",'历史数据'!G2/'历史数据'!H2-1) | G11: =IF(OR('历史数据'!G2<=0,'历史数据'!I2<=0),"",POWER('历史数据'!G2/'历史数据'!I2,1/3)-1) | H11: =IF(OR('历史数据'!G2<=0,'历史数据'!J2=""),"",('历史数据'!G2-'历史数据'!J2)/'历史数据'!G2) | I11: =IF(OR(H11="",'历史数据'!H2<=0,'历史数据'!K2=""),"",(H11-('历史数据'!H2-'历史数据'!K2)/'历史数据'!H2)*100) | J11: =IF(OR(H11="",'历史数据'!I2<=0,'历史数据'!L2=""),"",(H11-('历史数据'!I2-'历史数据'!L2)/'历史数据'!I2)*100) | K11: =IF('历史数据'!M2="","",'历史数据'!M2/100000000) | L11: =IF(OR('历史数据'!G2=0,'历史数据'!M2=""),"",'历史数据'!M2/'历史数据'!G2) | M11: =IF(OR('历史数据'!M2="",'历史数据'!N2=0),"",('历史数据'!M2-'历史数据'!N2)/ABS('历史数据'!N2)) | N11: =IF(OR('历史数据'!M2<=0,'历史数据'!O2<=0),"",POWER('历史数据'!M2/'历史数据'!O2,1/3)-1) | O11: =IF('历史数据'!P2="","",'历史数据'!P2/100000000) | P11: =IF(OR('历史数据'!P2="",'历史数据'!Q2=0),"",('历史数据'!P2-'历史数据'!Q2)/ABS('历史数据'!Q2)) | Q11: =IF(OR('历史数据'!P2<=0,'历史数据'!R2<=0),"",POWER('历史数据'!P2/'历史数据'!R2,1/3)-1) | R11: =IF('历史数据'!S2="","",'历史数据'!S2/100000000) | S11: =IF('历史数据'!T2="","",'历史数据'!T2) | T11: =IF('历史数据'!U2="","",'历史数据'!U2) | U11: =IF('历史数据'!V2="","",'历史数据'!V2/100000000) | V11: =IF('历史数据'!W2="","",'历史数据'!W2/100000000) | W11: =IF('历史数据'!X2="","",'历史数据'!X2) | X11: =IF(OR(R11="",V11<=0),"",R11/V11-1) | Y11: =IF('历史数据'!Y2="","",'历史数据'!Y2) | Z11: =IF('历史数据'!Z2="","",'历史数据'!Z2/100000000) | AA11: =IF('历史数据'!AA2="","",'历史数据'!AA2/100000000) | AB11: =IF('历史数据'!AB2="","",'历史数据'!AB2/100000000) | AC11: 近五个交易日资金净额:optional_missing；近一月资金净额（最近22个交易日）:optional_missing | AD11: SUCCESS
A12: 920976 | B12: 视声智能 | C12: =IF('历史数据'!D7="","",'历史数据'!D7) | D12: =IF('历史数据'!E7="","",'历史数据'!E7) | E12: =IF('历史数据'!G7="","",'历史数据'!G7/100000000) | F12: =IF(OR('历史数据'!G7="",'历史数据'!H7<=0),"",'历史数据'!G7/'历史数据'!H7-1) | G12: =IF(OR('历史数据'!G7<=0,'历史数据'!I7<=0),"",POWER('历史数据'!G7/'历史数据'!I7,1/3)-1) | H12: =IF(OR('历史数据'!G7<=0,'历史数据'!J7=""),"",('历史数据'!G7-'历史数据'!J7)/'历史数据'!G7) | I12: =IF(OR(H12="",'历史数据'!H7<=0,'历史数据'!K7=""),"",(H12-('历史数据'!H7-'历史数据'!K7)/'历史数据'!H7)*100) | J12: =IF(OR(H12="",'历史数据'!I7<=0,'历史数据'!L7=""),"",(H12-('历史数据'!I7-'历史数据'!L7)/'历史数据'!I7)*100) | K12: =IF('历史数据'!M7="","",'历史数据'!M7/100000000) | L12: =IF(OR('历史数据'!G7=0,'历史数据'!M7=""),"",'历史数据'!M7/'历史数据'!G7) | M12: =IF(OR('历史数据'!M7="",'历史数据'!N7=0),"",('历史数据'!M7-'历史数据'!N7)/ABS('历史数据'!N7)) | N12: =IF(OR('历史数据'!M7<=0,'历史数据'!O7<=0),"",POWER('历史数据'!M7/'历史数据'!O7,1/3)-1) | O12: =IF('历史数据'!P7="","",'历史数据'!P7/100000000) | P12: =IF(OR('历史数据'!P7="",'历史数据'!Q7=0),"",('历史数据'!P7-'历史数据'!Q7)/ABS('历史数据'!Q7)) | Q12: =IF(OR('历史数据'!P7<=0,'历史数据'!R7<=0),"",POWER('历史数据'!P7/'历史数据'!R7,1/3)-1) | R12: =IF('历史数据'!S7="","",'历史数据'!S7/100000000) | S12: =IF('历史数据'!T7="","",'历史数据'!T7) | T12: =IF('历史数据'!U7="","",'历史数据'!U7) | U12: =IF('历史数据'!V7="","",'历史数据'!V7/100000000) | V12: =IF('历史数据'!W7="","",'历史数据'!W7/100000000) | W12: =IF('历史数据'!X7="","",'历史数据'!X7) | X12: =IF(OR(R12="",V12<=0),"",R12/V12-1) | Y12: =IF('历史数据'!Y7="","",'历史数据'!Y7) | Z12: =IF('历史数据'!Z7="","",'历史数据'!Z7/100000000) | AA12: =IF('历史数据'!AA7="","",'历史数据'!AA7/100000000) | AB12: =IF('历史数据'!AB7="","",'历史数据'!AB7/100000000) | AC12: 近五个交易日资金净额:optional_missing；近一月资金净额（最近22个交易日）:optional_missing | AD12: SUCCESS
A13: 920971 | B13: 天马新材 | C13: =IF('历史数据'!D9="","",'历史数据'!D9) | D13: =IF('历史数据'!E9="","",'历史数据'!E9) | E13: =IF('历史数据'!G9="","",'历史数据'!G9/100000000) | F13: =IF(OR('历史数据'!G9="",'历史数据'!H9<=0),"",'历史数据'!G9/'历史数据'!H9-1) | G13: =IF(OR('历史数据'!G9<=0,'历史数据'!I9<=0),"",POWER('历史数据'!G9/'历史数据'!I9,1/3)-1) | H13: =IF(OR('历史数据'!G9<=0,'历史数据'!J9=""),"",('历史数据'!G9-'历史数据'!J9)/'历史数据'!G9) | I13: =IF(OR(H13="",'历史数据'!H9<=0,'历史数据'!K9=""),"",(H13-('历史数据'!H9-'历史数据'!K9)/'历史数据'!H9)*100) | J13: =IF(OR(H13="",'历史数据'!I9<=0,'历史数据'!L9=""),"",(H13-('历史数据'!I9-'历史数据'!L9)/'历史数据'!I9)*100) | K13: =IF('历史数据'!M9="","",'历史数据'!M9/100000000) | L13: =IF(OR('历史数据'!G9=0,'历史数据'!M9=""),"",'历史数据'!M9/'历史数据'!G9) | M13: =IF(OR('历史数据'!M9="",'历史数据'!N9=0),"",('历史数据'!M9-'历史数据'!N9)/ABS('历史数据'!N9)) | N13: =IF(OR('历史数据'!M9<=0,'历史数据'!O9<=0),"",POWER('历史数据'!M9/'历史数据'!O9,1/3)-1) | O13: =IF('历史数据'!P9="","",'历史数据'!P9/100000000) | P13: =IF(OR('历史数据'!P9="",'历史数据'!Q9=0),"",('历史数据'!P9-'历史数据'!Q9)/ABS('历史数据'!Q9)) | Q13: =IF(OR('历史数据'!P9<=0,'历史数据'!R9<=0),"",POWER('历史数据'!P9/'历史数据'!R9,1/3)-1) | R13: =IF('历史数据'!S9="","",'历史数据'!S9/100000000) | S13: =IF('历史数据'!T9="","",'历史数据'!T9) | T13: =IF('历史数据'!U9="","",'历史数据'!U9) | U13: =IF('历史数据'!V9="","",'历史数据'!V9/100000000) | V13: =IF('历史数据'!W9="","",'历史数据'!W9/100000000) | W13: =IF('历史数据'!X9="","",'历史数据'!X9) | X13: =IF(OR(R13="",V13<=0),"",R13/V13-1) | Y13: =IF('历史数据'!Y9="","",'历史数据'!Y9) | Z13: =IF('历史数据'!Z9="","",'历史数据'!Z9/100000000) | AA13: =IF('历史数据'!AA9="","",'历史数据'!AA9/100000000) | AB13: =IF('历史数据'!AB9="","",'历史数据'!AB9/100000000) | AC13: 近五个交易日资金净额:optional_missing；近一月资金净额（最近22个交易日）:optional_missing | AD13: SUCCESS
A14: 920970 | B14: 大禹生物 | C14: =IF('历史数据'!D10="","",'历史数据'!D10) | D14: =IF('历史数据'!E10="","",'历史数据'!E10) | E14: =IF('历史数据'!G10="","",'历史数据'!G10/100000000) | F14: =IF(OR('历史数据'!G10="",'历史数据'!H10<=0),"",'历史数据'!G10/'历史数据'!H10-1) | G14: =IF(OR('历史数据'!G10<=0,'历史数据'!I10<=0),"",POWER('历史数据'!G10/'历史数据'!I10,1/3)-1) | H14: =IF(OR('历史数据'!G10<=0,'历史数据'!J10=""),"",('历史数据'!G10-'历史数据'!J10)/'历史数据'!G10) | I14: =IF(OR(H14="",'历史数据'!H10<=0,'历史数据'!K10=""),"",(H14-('历史数据'!H10-'历史数据'!K10)/'历史数据'!H10)*100) | J14: =IF(OR(H14="",'历史数据'!I10<=0,'历史数据'!L10=""),"",(H14-('历史数据'!I10-'历史数据'!L10)/'历史数据'!I10)*100) | K14: =IF('历史数据'!M10="","",'历史数据'!M10/100000000) | L14: =IF(OR('历史数据'!G10=0,'历史数据'!M10=""),"",'历史数据'!M10/'历史数据'!G10) | M14: =IF(OR('历史数据'!M10="",'历史数据'!N10=0),"",('历史数据'!M10-'历史数据'!N10)/ABS('历史数据'!N10)) | N14: =IF(OR('历史数据'!M10<=0,'历史数据'!O10<=0),"",POWER('历史数据'!M10/'历史数据'!O10,1/3)-1) | O14: =IF('历史数据'!P10="","",'历史数据'!P10/100000000) | P14: =IF(OR('历史数据'!P10="",'历史数据'!Q10=0),"",('历史数据'!P10-'历史数据'!Q10)/ABS('历史数据'!Q10)) | Q14: =IF(OR('历史数据'!P10<=0,'历史数据'!R10<=0),"",POWER('历史数据'!P10/'历史数据'!R10,1/3)-1) | R14: =IF('历史数据'!S10="","",'历史数据'!S10/100000000) | S14: =IF('历史数据'!T10="","",'历史数据'!T10) | T14: =IF('历史数据'!U10="","",'历史数据'!U10) | U14: =IF('历史数据'!V10="","",'历史数据'!V10/100000000) | V14: =IF('历史数据'!W10="","",'历史数据'!W10/100000000) | W14: =IF('历史数据'!X10="","",'历史数据'!X10) | X14: =IF(OR(R14="",V14<=0),"",R14/V14-1) | Y14: =IF('历史数据'!Y10="","",'历史数据'!Y10) | Z14: =IF('历史数据'!Z10="","",'历史数据'!Z10/100000000) | AA14: =IF('历史数据'!AA10="","",'历史数据'!AA10/100000000) | AB14: =IF('历史数据'!AB10="","",'历史数据'!AB10/100000000) | AC14: 近五个交易日资金净额:optional_missing；近一月资金净额（最近22个交易日）:optional_missing | AD14: SUCCESS

Sheet 港股
A1: 股票分析表生成器｜财务年度 2025｜交易统计年度 2026｜运行日期 2026-08-29｜金额：亿元；股数：亿股
A2: 范围：港交所普通股；仅纳入可取得结构化关键财务数据的公司。港股大宗交易和资金流允许留空。
A3: 公司信息 | E3: 营业收入 | H3: 毛利率 | K3: 归母净利润 | O3: 经营活动现金流 | R3: 上市发行与市场交易 | AC3: 数据状态
A4: 证券代码 | B4: 公司名称 | C4: 实际报告期 | D4: 报表币种 | E4: 2025年营业收入 | F4: 营业收入同比 | G4: 营业收入三年 CAGR | H4: 毛利率 | I4: 毛利率同比变化（百分点） | J4: 毛利率三年变化（百分点） | K4: 归母净利润 | L4: 归母净利率 | M4: 归母净利润同比 | N4: 归母净利润三年 CAGR | O4: 经营活动现金流净额 | P4: 经营活动现金流同比 | Q4: 经营活动现金流三年 CAGR | R4: 最新总市值 | S4: 上市日期 | T4: 发行价 | U4: 发行股数 | V4: 发行时总市值 | W4: 现价 | X4: 市值增长率 | Y4: 当年累计大宗交易笔数 | Z4: 当年累计大宗交易金额 | AA4: 近五个交易日资金净额 | AB4: 近一月资金净额（最近22个交易日） | AC4: 字段状态摘要 | AD4: 公司状态

Sheet 历史数据
A1: 市场 | B1: 证券代码 | C1: 公司名 | D1: 本期报告日 | E1: 标准币种 | F1: 原币种 | G1: 本期营业收入 | H1: 上期营业收入 | I1: 三年前营业收入 | J1: 本期营业成本 | K1: 上期营业成本 | L1: 三年前营业成本 | M1: 本期归母净利润 | N1: 上期归母净利润 | O1: 三年前归母净利润 | P1: 本期经营现金流 | Q1: 上期经营现金流 | R1: 三年前经营现金流 | S1: 最新市值 | T1: 上市日期 | U1: 发行价 | V1: 发行股数 | W1: 发行时市值 | X1: 现价 | Y1: 大宗交易数量 | Z1: 大宗交易金额 | AA1: 近五日资金净额 | AB1: 近一月资金净额 | AC1: 是否合并口径 | AD1: 是否追溯调整 | AE1: 财务质量说明
A2: A股 | B2: 920992 | C2: 中科美菱 | D2: 46022 | E2: CNY | F2: CNY | G2: 3.085449e+08 | H2: 2.9577328e+08 | I2: 4.0648909e+08 | J2: 1.9710165e+08 | K2: 1.8880456e+08 | L2: 2.513263e+08 | M2: 19107093 | N2: 18087030 | O2: 52586941 | P2: 29447537 | Q2: 25513233 | R2: -38010376 | S2: 1103699957 | T2: 44852 | U2: 16 | V2: 24182734 | W2: 386923744 | X2: 11.41 | Y2: 0 | Z2: 0
A3: A股 | B3: 920985 | C3: 海泰新能 | D3: 46022 | E3: CNY | F3: CNY | G3: 1.6508446e+09 | H3: 3.717455e+09 | I3: 6.3871653e+09 | J3: 1.7340237e+09 | K3: 2.9877562e+09 | L3: 6.0093425e+09 | M3: -6.7459469e+08 | N3: 1.8948975e+08 | O3: 1.1860557e+08 | P3: -7.8340685e+08 | Q3: 2.0788911e+08 | R3: 70336940 | S3: 1442159092 | T3: 44781 | U3: 9.05 | V3: 53821948 | W3: 4.8708863e+08 | X3: 4.66 | Y3: 0 | Z3: 0
A4: A股 | B4: 920982 | C4: 锦波生物 | D4: 46022 | E4: CNY | F4: CNY | G4: 1.5953729e+09 | H4: 1.4428314e+09 | I4: 3.901984e+08 | J4: 1.7211966e+08 | K4: 1.1519969e+08 | L4: 56828644 | M4: 6.5212897e+08 | N4: 7.3230162e+08 | O4: 1.0917501e+08 | P4: 6.3000219e+08 | Q4: 7.6715539e+08 | R4: 1.2389108e+08 | S4: 13921755487 | T4: 45127 | U4: 49 | V4: 5000000 | W4: 245000000 | X4: 120.99 | Y4: 0 | Z4: 0
A5: A股 | B5: 920981 | C5: 晶赛科技 | D5: 46022 | E5: CNY | F5: CNY | G5: 5.7687093e+08 | H5: 5.252193e+08 | I5: 3.8726666e+08 | J5: 5.0672793e+08 | K5: 4.5606995e+08 | L5: 3.1411464e+08 | M5: 9683732.1 | N5: 5923743.4 | O5: 43595333 | P5: 81541093 | Q5: 12791072 | R5: 62891118 | S5: 2264982160 | T5: 44515 | U5: 18.32 | V5: 11878300 | W5: 217610456 | X5: 29.62 | Y5: 0 | Z5: 0
A6: A股 | B6: 920978 | C6: 开特股份 | D6: 46022 | E6: CNY | F6: CNY | G6: 1.1294723e+09 | H6: 8.2636294e+08 | I6: 5.1467766e+08 | J6: 7.668473e+08 | K6: 5.5657243e+08 | L6: 3.5493402e+08 | M6: 1.7315845e+08 | N6: 1.3784569e+08 | O6: 77385536 | P6: 1.6690427e+08 | Q6: 1.2574463e+08 | R6: -13887760 | S6: 3389936052 | T6: 45197 | U6: 7.37 | V6: 18000000 | W6: 132660000 | X6: 18.83 | Y6: 0 | Z6: 0
A7: A股 | B7: 920976 | C7: 视声智能 | D7: 46022 | E7: CNY | F7: CNY | G7: 3.0223543e+08 | H7: 2.4868323e+08 | I7: 2.3173282e+08 | J7: 1.342725e+08 | K7: 1.2051954e+08 | L7: 1.3102362e+08 | M7: 67325861 | N7: 47679451 | O7: 34064008 | P7: 63072630 | Q7: 51275635 | R7: 45506289 | S7: 1304123492 | T7: 45170 | U7: 10.3 | V7: 12700000 | W7: 130810000 | X7: 18.38 | Y7: 0 | Z7: 0
A8: A股 | B8: 920974 | C8: 凯大催化 | D8: 46022 | E8: CNY | F8: CNY | G8: 1.072309e+09 | H8: 1.0616081e+09 | I8: 1.6190736e+09 | J8: 1.0143807e+09 | K8: 1.0263661e+09 | L8: 1.5321391e+09 | M8: 25496094 | N8: 20325941 | O8: 61343932 | P8: -10472711 | Q8: 23628705 | R8: 14427236 | S8: 1033578000 | T8: 44993 | U8: 6.26 | V8: 10000000 | W8: 62600000 | X8: 6.31 | Y8: 0 | Z8: 0
A9: A股 | B9: 920971 | C9: 天马新材 | D9: 46022 | E9: CNY | F9: CNY | G9: 2.7365969e+08 | H9: 2.5484901e+08 | I9: 1.8593322e+08 | J9: 2.2510211e+08 | K9: 1.9315277e+08 | L9: 1.3202182e+08 | M9: 38164173 | N9: 39379874 | O9: 35635028 | P9: 18878197 | Q9: 6393064.1 | R9: -21303607 | S9: 2886151736 | T9: 44831 | U9: 21.38 | V9: 14406668 | W9: 3.0801456e+08 | X9: 27.76 | Y9: 0 | Z9: 0
A10: A股 | B10: 920970 | C10: 大禹生物 | D10: 46022 | E10: CNY | F10: CNY | G10: 1.6748061e+08 | H10: 1.2251196e+08 | I10: 1.5698306e+08 | J10: 1.5405047e+08 | K10: 91912540 | L10: 88219051 | M10: -29853181 | N10: -23942695 | O10: 18147190 | P10: 10181364 | Q10: 18393494 | R10: 26602938 | S10: 720205200 | T10: 44699 | U10: 10 | V10: 15000000 | W10: 150000000 | X10: 6.5 | Y10: 0 | Z10: 0
A11: A股 | B11: 920964 | C11: 润农节水 | D11: 46022 | E11: CNY | F11: CNY | G11: 1.0305636e+09 | H11: 9.8357532e+08 | I11: 6.5991558e+08 | J11: 8.9103677e+08 | K11: 8.3117106e+08 | L11: 5.2214632e+08 | M11: -16769482 | N11: 7948923 | O11: 49573273 | P11: -15295210 | Q11: 69506556 | R11: 68747531 | S11: 1358281600 | T11: 44039 | U11: 4.7 | V11: 40000000 | W11: 188000000 | X11: 5.2 | Y11: 0 | Z11: 0

Sheet 数据来源
A1: 市场 | B1: 证券代码 | C1: 公司名 | D1: 字段组 | E1: 来源名 | F1: 来源地址或请求标识 | G1: 抓取时间 | H1: 原币种 | I1: 标准币种 | J1: 状态 | K1: 缺失原因 | L1: 是否近似 | M1: 主数据源 | N1: 缓存命中
A2: A股 | B2: 920992 | C2: 中科美菱 | D2: 最新行情 | E2: 东方财富 | F2: push2 ulist.np/get f2,f20（按指定证券分批） | G2: 46263.262 | H2: CNY | I2: CNY | J2: ok | L2: FALSE | M2: 东方财富 | N2: FALSE
A3: A股 | B3: 920992 | C3: 中科美菱 | D3: 大宗交易 | E3: 东方财富 | F3: RPT_DATA_BLOCKTRADE 2026（全市场分页后本地聚合） | G3: 46263.262 | H3: CNY | I3: CNY | J3: ok | L3: FALSE | M3: 东方财富 | N3: FALSE
A4: A股 | B4: 920992 | C4: 中科美菱 | D4: 年度财务 | E4: 东方财富 | F4: RPT_LICO_FN_CPD + RPT_DMSK_FN_CASHFLOW；巨潮回退原因：未配置巨潮官方 API 凭证/端点（CNINFO_ACCESS_TOKEN、CNINFO_INCOME_API_URL、CNINFO_CASHFLOW_API_URL） | G4: 46263.262 | H4: CNY | I4: CNY | J4: ok | L4: TRUE | M4: 巨潮资讯（CNINFO Data Service） | N4: FALSE
A5: A股 | B5: 920992 | C5: 中科美菱 | D5: 上市与发行信息 | E5: 东方财富 | F5: RPT_PCF10_ORG_ISSUEINFO | G5: 46263.262 | H5: CNY | I5: CNY | J5: ok | L5: FALSE | M5: 东方财富 | N5: FALSE
A6: A股 | B6: 920992 | C6: 中科美菱 | D6: 资金流 | E6: 东方财富 | F6: fast-mode-no-reliable-batch-endpoint | G6: 46263.262 | I6: CNY | J6: optional_missing | K6: 快速模式未发现可靠的批量近五个交易日同口径字段，为避免逐股慢请求，本次留空 | L6: FALSE | M6: 东方财富 | N6: FALSE
A7: A股 | B7: 920985 | C7: 海泰新能 | D7: 最新行情 | E7: 东方财富 | F7: push2 ulist.np/get f2,f20（按指定证券分批） | G7: 46263.262 | H7: CNY | I7: CNY | J7: ok | L7: FALSE | M7: 东方财富 | N7: FALSE
A8: A股 | B8: 920985 | C8: 海泰新能 | D8: 大宗交易 | E8: 东方财富 | F8: RPT_DATA_BLOCKTRADE 2026（全市场分页后本地聚合） | G8: 46263.262 | H8: CNY | I8: CNY | J8: ok | L8: FALSE | M8: 东方财富 | N8: FALSE
A9: A股 | B9: 920985 | C9: 海泰新能 | D9: 年度财务 | E9: 东方财富 | F9: RPT_LICO_FN_CPD + RPT_DMSK_FN_CASHFLOW；巨潮回退原因：未配置巨潮官方 API 凭证/端点（CNINFO_ACCESS_TOKEN、CNINFO_INCOME_API_URL、CNINFO_CASHFLOW_API_URL） | G9: 46263.262 | H9: CNY | I9: CNY | J9: ok | L9: TRUE | M9: 巨潮资讯（CNINFO Data Service） | N9: FALSE
A10: A股 | B10: 920985 | C10: 海泰新能 | D10: 上市与发行信息 | E10: 东方财富 | F10: RPT_PCF10_ORG_ISSUEINFO | G10: 46263.262 | H10: CNY | I10: CNY | J10: ok | L10: FALSE | M10: 东方财富 | N10: FALSE
A11: A股 | B11: 920985 | C11: 海泰新能 | D11: 资金流 | E11: 东方财富 | F11: fast-mode-no-reliable-batch-endpoint | G11: 46263.262 | I11: CNY | J11: optional_missing | K11: 快速模式未发现可靠的批量近五个交易日同口径字段，为避免逐股慢请求，本次留空 | L11: FALSE | M11: 东方财富 | N11: FALSE
A12: A股 | B12: 920982 | C12: 锦波生物 | D12: 最新行情 | E12: 东方财富 | F12: push2 ulist.np/get f2,f20（按指定证券分批） | G12: 46263.262 | H12: CNY | I12: CNY | J12: ok | L12: FALSE | M12: 东方财富 | N12: FALSE
A13: A股 | B13: 920982 | C13: 锦波生物 | D13: 大宗交易 | E13: 东方财富 | F13: RPT_DATA_BLOCKTRADE 2026（全市场分页后本地聚合） | G13: 46263.262 | H13: CNY | I13: CNY | J13: ok | L13: FALSE | M13: 东方财富 | N13: FALSE
A14: A股 | B14: 920982 | C14: 锦波生物 | D14: 年度财务 | E14: 东方财富 | F14: RPT_LICO_FN_CPD + RPT_DMSK_FN_CASHFLOW；巨潮回退原因：未配置巨潮官方 API 凭证/端点（CNINFO_ACCESS_TOKEN、CNINFO_INCOME_API_URL、CNINFO_CASHFLOW_API_URL） | G14: 46263.262 | H14: CNY | I14: CNY | J14: ok | L14: TRUE | M14: 巨潮资讯（CNINFO Data Service） | N14: FALSE
A15: A股 | B15: 920982 | C15: 锦波生物 | D15: 上市与发行信息 | E15: 东方财富 | F15: RPT_PCF10_ORG_ISSUEINFO | G15: 46263.262 | H15: CNY | I15: CNY | J15: ok | L15: FALSE | M15: 东方财富 | N15: FALSE
A16: A股 | B16: 920982 | C16: 锦波生物 | D16: 资金流 | E16: 东方财富 | F16: fast-mode-no-reliable-batch-endpoint | G16: 46263.262 | I16: CNY | J16: optional_missing | K16: 快速模式未发现可靠的批量近五个交易日同口径字段，为避免逐股慢请求，本次留空 | L16: FALSE | M16: 东方财富 | N16: FALSE
A17: A股 | B17: 920981 | C17: 晶赛科技 | D17: 最新行情 | E17: 东方财富 | F17: push2 ulist.np/get f2,f20（按指定证券分批） | G17: 46263.262 | H17: CNY | I17: CNY | J17: ok | L17: FALSE | M17: 东方财富 | N17: FALSE
A18: A股 | B18: 920981 | C18: 晶赛科技 | D18: 大宗交易 | E18: 东方财富 | F18: RPT_DATA_BLOCKTRADE 2026（全市场分页后本地聚合） | G18: 46263.262 | H18: CNY | I18: CNY | J18: ok | L18: FALSE | M18: 东方财富 | N18: FALSE
A19: A股 | B19: 920981 | C19: 晶赛科技 | D19: 年度财务 | E19: 东方财富 | F19: RPT_LICO_FN_CPD + RPT_DMSK_FN_CASHFLOW；巨潮回退原因：未配置巨潮官方 API 凭证/端点（CNINFO_ACCESS_TOKEN、CNINFO_INCOME_API_URL、CNINFO_CASHFLOW_API_URL） | G19: 46263.262 | H19: CNY | I19: CNY | J19: ok | L19: TRUE | M19: 巨潮资讯（CNINFO Data Service） | N19: FALSE
A20: A股 | B20: 920981 | C20: 晶赛科技 | D20: 上市与发行信息 | E20: 东方财富 | F20: RPT_PCF10_ORG_ISSUEINFO | G20: 46263.262 | H20: CNY | I20: CNY | J20: ok | L20: FALSE | M20: 东方财富 | N20: FALSE
A21: A股 | B21: 920981 | C21: 晶赛科技 | D21: 资金流 | E21: 东方财富 | F21: fast-mode-no-reliable-batch-endpoint | G21: 46263.262 | I21: CNY | J21: optional_missing | K21: 快速模式未发现可靠的批量近五个交易日同口径字段，为避免逐股慢请求，本次留空 | L21: FALSE | M21: 东方财富 | N21: FALSE
A22: A股 | B22: 920978 | C22: 开特股份 | D22: 最新行情 | E22: 东方财富 | F22: push2 ulist.np/get f2,f20（按指定证券分批） | G22: 46263.262 | H22: CNY | I22: CNY | J22: ok | L22: FALSE | M22: 东方财富 | N22: FALSE
A23: A股 | B23: 920978 | C23: 开特股份 | D23: 大宗交易 | E23: 东方财富 | F23: RPT_DATA_BLOCKTRADE 2026（全市场分页后本地聚合） | G23: 46263.262 | H23: CNY | I23: CNY | J23: ok | L23: FALSE | M23: 东方财富 | N23: FALSE
A24: A股 | B24: 920978 | C24: 开特股份 | D24: 年度财务 | E24: 东方财富 | F24: RPT_LICO_FN_CPD + RPT_DMSK_FN_CASHFLOW；巨潮回退原因：未配置巨潮官方 API 凭证/端点（CNINFO_ACCESS_TOKEN、CNINFO_INCOME_API_URL、CNINFO_CASHFLOW_API_URL） | G24: 46263.262 | H24: CNY | I24: CNY | J24: ok | L24: TRUE | M24: 巨潮资讯（CNINFO Data Service） | N24: FALSE
A25: A股 | B25: 920978 | C25: 开特股份 | D25: 上市与发行信息 | E25: 东方财富 | F25: RPT_PCF10_ORG_ISSUEINFO | G25: 46263.262 | H25: CNY | I25: CNY | J25: ok | L25: FALSE | M25: 东方财富 | N25: FALSE
A26: A股 | B26: 920978 | C26: 开特股份 | D26: 资金流 | E26: 东方财富 | F26: fast-mode-no-reliable-batch-endpoint | G26: 46263.262 | I26: CNY | J26: optional_missing | K26: 快速模式未发现可靠的批量近五个交易日同口径字段，为避免逐股慢请求，本次留空 | L26: FALSE | M26: 东方财富 | N26: FALSE
A27: A股 | B27: 920976 | C27: 视声智能 | D27: 最新行情 | E27: 东方财富 | F27: push2 ulist.np/get f2,f20（按指定证券分批） | G27: 46263.262 | H27: CNY | I27: CNY | J27: ok | L27: FALSE | M27: 东方财富 | N27: FALSE
A28: A股 | B28: 920976 | C28: 视声智能 | D28: 大宗交易 | E28: 东方财富 | F28: RPT_DATA_BLOCKTRADE 2026（全市场分页后本地聚合） | G28: 46263.262 | H28: CNY | I28: CNY | J28: ok | L28: FALSE | M28: 东方财富 | N28: FALSE
A29: A股 | B29: 920976 | C29: 视声智能 | D29: 年度财务 | E29: 东方财富 | F29: RPT_LICO_FN_CPD + RPT_DMSK_FN_CASHFLOW；巨潮回退原因：未配置巨潮官方 API 凭证/端点（CNINFO_ACCESS_TOKEN、CNINFO_INCOME_API_URL、CNINFO_CASHFLOW_API_URL） | G29: 46263.262 | H29: CNY | I29: CNY | J29: ok | L29: TRUE | M29: 巨潮资讯（CNINFO Data Service） | N29: FALSE
A30: A股 | B30: 920976 | C30: 视声智能 | D30: 上市与发行信息 | E30: 东方财富 | F30: RPT_PCF10_ORG_ISSUEINFO | G30: 46263.262 | H30: CNY | I30: CNY | J30: ok | L30: FALSE | M30: 东方财富 | N30: FALSE
A31: A股 | B31: 920976 | C31: 视声智能 | D31: 资金流 | E31: 东方财富 | F31: fast-mode-no-reliable-batch-endpoint | G31: 46263.262 | I31: CNY | J31: optional_missing | K31: 快速模式未发现可靠的批量近五个交易日同口径字段，为避免逐股慢请求，本次留空 | L31: FALSE | M31: 东方财富 | N31: FALSE
A32: A股 | B32: 920974 | C32: 凯大催化 | D32: 最新行情 | E32: 东方财富 | F32: push2 ulist.np/get f2,f20（按指定证券分批） | G32: 46263.262 | H32: CNY | I32: CNY | J32: ok | L32: FALSE | M32: 东方财富 | N32: FALSE
A33: A股 | B33: 920974 | C33: 凯大催化 | D33: 大宗交易 | E33: 东方财富 | F33: RPT_DATA_BLOCKTRADE 2026（全市场分页后本地聚合） | G33: 46263.262 | H33: CNY | I33: CNY | J33: ok | L33: FALSE | M33: 东方财富 | N33: FALSE
A34: A股 | B34: 920974 | C34: 凯大催化 | D34: 年度财务 | E34: 东方财富 | F34: RPT_LICO_FN_CPD + RPT_DMSK_FN_CASHFLOW；巨潮回退原因：未配置巨潮官方 API 凭证/端点（CNINFO_ACCESS_TOKEN、CNINFO_INCOME_API_URL、CNINFO_CASHFLOW_API_URL） | G34: 46263.262 | H34: CNY | I34: CNY | J34: ok | L34: TRUE | M34: 巨潮资讯（CNINFO Data Service） | N34: FALSE
A35: A股 | B35: 920974 | C35: 凯大催化 | D35: 上市与发行信息 | E35: 东方财富 | F35: RPT_PCF10_ORG_ISSUEINFO | G35: 46263.262 | H35: CNY | I35: CNY | J35: ok | L35: FALSE | M35: 东方财富 | N35: FALSE
A36: A股 | B36: 920974 | C36: 凯大催化 | D36: 资金流 | E36: 东方财富 | F36: fast-mode-no-reliable-batch-endpoint | G36: 46263.262 | I36: CNY | J36: optional_missing | K36: 快速模式未发现可靠的批量近五个交易日同口径字段，为避免逐股慢请求，本次留空 | L36: FALSE | M36: 东方财富 | N36: FALSE
A37: A股 | B37: 920971 | C37: 天马新材 | D37: 最新行情 | E37: 东方财富 | F37: push2 ulist.np/get f2,f20（按指定证券分批） | G37: 46263.262 | H37: CNY | I37: CNY | J37: ok | L37: FALSE | M37: 东方财富 | N37: FALSE
A38: A股 | B38: 920971 | C38: 天马新材 | D38: 大宗交易 | E38: 东方财富 | F38: RPT_DATA_BLOCKTRADE 2026（全市场分页后本地聚合） | G38: 46263.262 | H38: CNY | I38: CNY | J38: ok | L38: FALSE | M38: 东方财富 | N38: FALSE
A39: A股 | B39: 920971 | C39: 天马新材 | D39: 年度财务 | E39: 东方财富 | F39: RPT_LICO_FN_CPD + RPT_DMSK_FN_CASHFLOW；巨潮回退原因：未配置巨潮官方 API 凭证/端点（CNINFO_ACCESS_TOKEN、CNINFO_INCOME_API_URL、CNINFO_CASHFLOW_API_URL） | G39: 46263.262 | H39: CNY | I39: CNY | J39: ok | L39: TRUE | M39: 巨潮资讯（CNINFO Data Service） | N39: FALSE
A40: A股 | B40: 920971 | C40: 天马新材 | D40: 上市与发行信息 | E40: 东方财富 | F40: RPT_PCF10_ORG_ISSUEINFO | G40: 46263.262 | H40: CNY | I40: CNY | J40: ok | L40: FALSE | M40: 东方财富 | N40: FALSE
...

Sheet 异常记录
A1: 市场 | B1: 证券代码 | C1: 公司名称 | D1: 字段名 | E1: 字段状态 | F1: 原因 | G1: 是否核心字段 | H1: 是否允许为空 | I1: 主数据源 | J1: 实际数据源 | K1: 请求端点 | L1: 抓取时间 | M1: 缓存命中情况
A2: A股 | B2: 920992 | C2: 中科美菱 | D2: 资金流 | E2: optional_missing | F2: 快速模式未发现可靠的批量近五个交易日同口径字段，为避免逐股慢请求，本次留空 | G2: FALSE | H2: TRUE | I2: 东方财富 | J2: 东方财富 | K2: fast-mode-no-reliable-batch-endpoint | L2: 46263.262 | M2: FALSE
A3: A股 | B3: 920992 | C3: 中科美菱 | D3: 近五个交易日资金净额 | E3: optional_missing | F3: 近五个交易日资金净额：optional_missing | G3: FALSE | H3: TRUE | M3: FALSE
A4: A股 | B4: 920992 | C4: 中科美菱 | D4: 近一月资金净额（最近22个交易日） | E4: optional_missing | F4: 近一月资金净额（最近22个交易日）：optional_missing | G4: FALSE | H4: TRUE | M4: FALSE
A5: A股 | B5: 920985 | C5: 海泰新能 | D5: 资金流 | E5: optional_missing | F5: 快速模式未发现可靠的批量近五个交易日同口径字段，为避免逐股慢请求，本次留空 | G5: FALSE | H5: TRUE | I5: 东方财富 | J5: 东方财富 | K5: fast-mode-no-reliable-batch-endpoint | L5: 46263.262 | M5: FALSE
A6: A股 | B6: 920985 | C6: 海泰新能 | D6: 近五个交易日资金净额 | E6: optional_missing | F6: 近五个交易日资金净额：optional_missing | G6: FALSE | H6: TRUE | M6: FALSE
A7: A股 | B7: 920985 | C7: 海泰新能 | D7: 近一月资金净额（最近22个交易日） | E7: optional_missing | F7: 近一月资金净额（最近22个交易日）：optional_missing | G7: FALSE | H7: TRUE | M7: FALSE
A8: A股 | B8: 920982 | C8: 锦波生物 | D8: 资金流 | E8: optional_missing | F8: 快速模式未发现可靠的批量近五个交易日同口径字段，为避免逐股慢请求，本次留空 | G8: FALSE | H8: TRUE | I8: 东方财富 | J8: 东方财富 | K8: fast-mode-no-reliable-batch-endpoint | L8: 46263.262 | M8: FALSE
A9: A股 | B9: 920982 | C9: 锦波生物 | D9: 近五个交易日资金净额 | E9: optional_missing | F9: 近五个交易日资金净额：optional_missing | G9: FALSE | H9: TRUE | M9: FALSE
A10: A股 | B10: 920982 | C10: 锦波生物 | D10: 近一月资金净额（最近22个交易日） | E10: optional_missing | F10: 近一月资金净额（最近22个交易日）：optional_missing | G10: FALSE | H10: TRUE | M10: FALSE
A11: A股 | B11: 920981 | C11: 晶赛科技 | D11: 资金流 | E11: optional_missing | F11: 快速模式未发现可靠的批量近五个交易日同口径字段，为避免逐股慢请求，本次留空 | G11: FALSE | H11: TRUE | I11: 东方财富 | J11: 东方财富 | K11: fast-mode-no-reliable-batch-endpoint | L11: 46263.262 | M11: FALSE
A12: A股 | B12: 920981 | C12: 晶赛科技 | D12: 近五个交易日资金净额 | E12: optional_missing | F12: 近五个交易日资金净额：optional_missing | G12: FALSE | H12: TRUE | M12: FALSE
A13: A股 | B13: 920981 | C13: 晶赛科技 | D13: 近一月资金净额（最近22个交易日） | E13: optional_missing | F13: 近一月资金净额（最近22个交易日）：optional_missing | G13: FALSE | H13: TRUE | M13: FALSE
A14: A股 | B14: 920978 | C14: 开特股份 | D14: 资金流 | E14: optional_missing | F14: 快速模式未发现可靠的批量近五个交易日同口径字段，为避免逐股慢请求，本次留空 | G14: FALSE | H14: TRUE | I14: 东方财富 | J14: 东方财富 | K14: fast-mode-no-reliable-batch-endpoint | L14: 46263.262 | M14: FALSE
A15: A股 | B15: 920978 | C15: 开特股份 | D15: 近五个交易日资金净额 | E15: optional_missing | F15: 近五个交易日资金净额：optional_missing | G15: FALSE | H15: TRUE | M15: FALSE
A16: A股 | B16: 920978 | C16: 开特股份 | D16: 近一月资金净额（最近22个交易日） | E16: optional_missing | F16: 近一月资金净额（最近22个交易日）：optional_missing | G16: FALSE | H16: TRUE | M16: FALSE
A17: A股 | B17: 920976 | C17: 视声智能 | D17: 资金流 | E17: optional_missing | F17: 快速模式未发现可靠的批量近五个交易日同口径字段，为避免逐股慢请求，本次留空 | G17: FALSE | H17: TRUE | I17: 东方财富 | J17: 东方财富 | K17: fast-mode-no-reliable-batch-endpoint | L17: 46263.262 | M17: FALSE
A18: A股 | B18: 920976 | C18: 视声智能 | D18: 近五个交易日资金净额 | E18: optional_missing | F18: 近五个交易日资金净额：optional_missing | G18: FALSE | H18: TRUE | M18: FALSE
A19: A股 | B19: 920976 | C19: 视声智能 | D19: 近一月资金净额（最近22个交易日） | E19: optional_missing | F19: 近一月资金净额（最近22个交易日）：optional_missing | G19: FALSE | H19: TRUE | M19: FALSE
A20: A股 | B20: 920974 | C20: 凯大催化 | D20: 资金流 | E20: optional_missing | F20: 快速模式未发现可靠的批量近五个交易日同口径字段，为避免逐股慢请求，本次留空 | G20: FALSE | H20: TRUE | I20: 东方财富 | J20: 东方财富 | K20: fast-mode-no-reliable-batch-endpoint | L20: 46263.262 | M20: FALSE
A21: A股 | B21: 920974 | C21: 凯大催化 | D21: 近五个交易日资金净额 | E21: optional_missing | F21: 近五个交易日资金净额：optional_missing | G21: FALSE | H21: TRUE | M21: FALSE
A22: A股 | B22: 920974 | C22: 凯大催化 | D22: 近一月资金净额（最近22个交易日） | E22: optional_missing | F22: 近一月资金净额（最近22个交易日）：optional_missing | G22: FALSE | H22: TRUE | M22: FALSE
A23: A股 | B23: 920971 | C23: 天马新材 | D23: 资金流 | E23: optional_missing | F23: 快速模式未发现可靠的批量近五个交易日同口径字段，为避免逐股慢请求，本次留空 | G23: FALSE | H23: TRUE | I23: 东方财富 | J23: 东方财富 | K23: fast-mode-no-reliable-batch-endpoint | L23: 46263.262 | M23: FALSE
A24: A股 | B24: 920971 | C24: 天马新材 | D24: 近五个交易日资金净额 | E24: optional_missing | F24: 近五个交易日资金净额：optional_missing | G24: FALSE | H24: TRUE | M24: FALSE
A25: A股 | B25: 920971 | C25: 天马新材 | D25: 近一月资金净额（最近22个交易日） | E25: optional_missing | F25: 近一月资金净额（最近22个交易日）：optional_missing | G25: FALSE | H25: TRUE | M25: FALSE
A26: A股 | B26: 920970 | C26: 大禹生物 | D26: 资金流 | E26: optional_missing | F26: 快速模式未发现可靠的批量近五个交易日同口径字段，为避免逐股慢请求，本次留空 | G26: FALSE | H26: TRUE | I26: 东方财富 | J26: 东方财富 | K26: fast-mode-no-reliable-batch-endpoint | L26: 46263.262 | M26: FALSE
A27: A股 | B27: 920970 | C27: 大禹生物 | D27: 近五个交易日资金净额 | E27: optional_missing | F27: 近五个交易日资金净额：optional_missing | G27: FALSE | H27: TRUE | M27: FALSE
A28: A股 | B28: 920970 | C28: 大禹生物 | D28: 近一月资金净额（最近22个交易日） | E28: optional_missing | F28: 近一月资金净额（最近22个交易日）：optional_missing | G28: FALSE | H28: TRUE | M28: FALSE
A29: A股 | B29: 920964 | C29: 润农节水 | D29: 资金流 | E29: optional_missing | F29: 快速模式未发现可靠的批量近五个交易日同口径字段，为避免逐股慢请求，本次留空 | G29: FALSE | H29: TRUE | I29: 东方财富 | J29: 东方财富 | K29: fast-mode-no-reliable-batch-endpoint | L29: 46263.262 | M29: FALSE
A30: A股 | B30: 920964 | C30: 润农节水 | D30: 近五个交易日资金净额 | E30: optional_missing | F30: 近五个交易日资金净额：optional_missing | G30: FALSE | H30: TRUE | M30: FALSE
A31: A股 | B31: 920964 | C31: 润农节水 | D31: 近一月资金净额（最近22个交易日） | E31: optional_missing | F31: 近一月资金净额（最近22个交易日）：optional_missing | G31: FALSE | H31: TRUE | M31: FALSE

Sheet 运行信息
A1: 项目 | B1: 值
A2: 程序英文名 | B2: StockAnalysis
A3: 程序中文名 | B3: 股票分析表生成器
A4: 程序版本 | B4: 0.2.0
A5: Python 版本 | B5: 3.12.13 (main, Aug 7 2026, 02:26:41) [MSC v.1944 64 bit (AMD64)]
A6: 操作系统 | B6: Windows-11-10.0.26200-SP0
A7: 运行时间 | B7: 2026-08-29T06:17:16.844945+00:00
A8: 配置快照 | B8: {"concurrency": 4, "financial_year": 2025, "fixture_mode": false, "flow_mode": "快速模式（默认）", "include_financial": true, "include_st": true, "markets": ["A股"], "max_a_share_companies": 10, "max_companies": 10, "max_hk_companies": 0, "network_mode": "国内数据源优先直连", "output_directory": "D:/python_software/StockAnalysis/artifacts/performance_output", "request_interval": 0.05, "test_mode": false, "trading_year": 2026, "update_mode": "强制刷新"}
A9: 成功数 | B9: 10
A10: 部分缺失数 | B10: 0
A11: 失败数 | B11: 0
A12: 排除数 | B12: 0
A13: 缓存命中数 | B13: 0
A14: 性能统计 | B14: {"cache_hits": 0, "circuit_breaks": 0, "direct_requests": 33, "http_elapsed_seconds": 4.461, "http_failures": 0, "http_requests": 33, "http_successes": 33, "negative_cache_hits": 0, "proxy_requests": 0, "requests_by_domain": {"datacenter-web.eastmoney.com": 21, "datacenter.eastmoney.com": 10, "push2delay.eastmoney.com": 2}, "requests_by_endpoint": {"batch-quotes-selected": 1, "block-trade-market-a-share": 1, "financial-cashflow-a-share": 10, "financial-income-a-share": 10, "ipo-A股": 10, "security-list-A股": 1}, "retries": 0, "stage_seconds": {"上市与发行信息": 0.626, "年度全市场大宗交易": 0.326, "年度财务": 1.135, "批量行情与市值": 0.058, "标准化、计算与校验": 0.001, "证券范围": 0.227, "资金流": 0.016}, "total_seconds": 2.389}
A15: 输出路径 | B15: D:\python_software\StockAnalysis\artifacts\performance_output\cold_10_a.xlsx
